Workbook

Sheet Part 1 - Overview
A1: Slide No | B1: Slide Title | C1: Metric / Data Point | D1: Value | E1: Notes / Key Message
A2: Slide 1 | B2: Title Slide | C2: Report Week | D2: 36 | E2: สรุปผลการดำเนินงานโครงการติดตั้งโครงข่ายโทรคมนาคม HAE และ TME ประจำสัปดาห์ที่ 36
A3: Slide 1 | B3: Executive Bottom Line | C3: HAE M1 Avg | D3: ='Part 2 - Aging'!D3 -> 3.1306306 | E3: หน้างานยังคงเดินหน้าอย่างรวดเร็ว แต่ระบบเอกสารยังมีปัญหาคอขวด
A4: Slide 1 | B4: Executive Bottom Line | C4: TME M1 Avg | D4: ='Part 2 - Aging'!D5 -> 15.031579 | E4: ข้อมูลดิบอาจมีความคลาดเคลื่อนในระบบ
A5: Slide 2 | B5: Portfolio Performance Snapshot | C5: Overall Progress | E5: สัดส่วนของ HAE และ TME ในพอร์ตโฟลิโอทั้งหมด
A6: Slide 2 | B6: Smart QC Overview | C6: Pass Rate | E6: อัตราการผ่านการตรวจสอบคุณภาพเปรียบเทียบสองโครงการ
A7: Slide 2 | B7: Operation Error & Defect Analysis | C7: Defect Issue 1 | E7: การขาดอุปกรณ์ป้องกัน PPE / ส่งข้อมูลไม่ครบ
A8: Slide 2 | B8: Improvement Plan for On-Site Quality | C8: Action Plan | E8: บูรณาการ AIS SPE Standards อย่างเคร่งครัด

Sheet Part 2 - Aging
A1: Slide No | B1: Slide Title | C1: Category / Person | D1: M1 Aging | E1: Notes
A2: Slide 3 | B2: The Execution Paradox | C2: Overall Bottleneck | E2: หน้างานทำได้เร็ว แต่กระบวนการตรวจรับเอกสารล่าช้า
A3: Slide 4 | B3: 1st Milestone AGING Analysis (HAE-MBB) | C3: HAE M1 | D3: =AVERAGEIF('2026'!G:G,"HAE",'2026'!BD:BD) -> 3.1306306 | E3: เปรียบเทียบระยะเวลาปิด M1 (HAE-MBB) | G3: HAE-MBB
A4: Slide 4 | B4: 2nd Milestone AGING Analysis (HAE-MBB) | C4: HAE M2 | D4: =AVERAGEIF('2026'!G:G,"HAE",'2026'!BE:BE) -> 6.6576577 | E4: ความท้าทายในการปิดเอกสาร M2 ที่กินระยะเวลานาน (HAE-MBB) | G4: HAE-MBB
A5: Slide 5 | B5: 1st Milestone AGING Analysis (TME-MBB) | C5: TME M1 | D5: =AVERAGEIF('2026'!G:G,"TME",'2026'!BE:BE) -> 15.031579 | E5: เปรียบเทียบระยะเวลาปิด M1(TME-MBB) | G5: TME-MBB
A6: Slide 5 | B6: 2nd Milestone AGING Analysis (TME-IPRAN) | C6: TME M2 | D6: 17.12 | E6: ความท้าทายในการปิดเอกสาร M2 ที่กินระยะเวลานาน (TME-IPRAN) | G6: TME-IPRAN
A7: Slide 5 | B7: 2nd Milestone AGING Analysis (TME-MBB) | C7: TME M2 | D7: 3.5 | E7: ความท้าทายในการปิดเอกสาร M2 ที่กินระยะเวลานาน (TME-MBB) | G7: TME-MBB
A8: Slide 6 | B8: Performance by PE Owner: Adisak (Average M1+M2) | C8: Adisak Chanmao (Average M1+M2) | D8: =AVERAGE(D3:D4) -> 4.8941441 | E8: HAE-MBB
A9: Slide 6 | B9: Performance by PE Owner: Palagon (Average M1+M2) | C9: Palagon Prommueangma (Average M1+M2) | D9: =AVERAGE(D4:D5) -> 10.844618 | E9: HAE-MBB
A10: Slide 7 | B10: Performance by PE Owner: Palagon (HAE) | C10: Palagon Prommueangma (Average M1+M2) | D10: =AVERAGEIF('2026'!R:R,"Palagon Prommueangma",'2026'!BD:BD) -> 4 | E10: HAE-MBB
A11: Slide 7 | B11: Performance by PE Owner: Palagon (TME) | C11: Palagon Prommueangma ((Average M1+M2) | D11: 5.37 | E11: TME-MBB | F11: 1.66 | G11: 2.3

Sheet Part 3 - Doc Management
A1: Slide No | B1: Slide Title | C1: Owner / Type | D1: Amount (THB) | E1: Done (THB) | F1: Avg Aging | G1: Notes
A2: Slide 8 | B2: Overall Team Install WK35 | C2: Overall Team Install WK35 | D2: 145006 | F2: 6 | G2: จำนวนงานติดตั้ง Completed WEEK 34
A3: Slide 8 | B3: Overall Team Install WK36 | C3: Overall Team Install WK36 | D3: 73027 | F3: 3 | G3: จำนวนงานติดตั้ง Completed WEEK 36
A4: Slide 9 | B4: DOC Owner: Hathairat Singkaew | C4: Hathairat (MBB/HAE) | F4: =AVERAGEIF('2026'!S:S, "น.ส. หทัยรัตน์ สิงห์แก้ว",'2026'!BE:BE) -> 8.2592593 | G4: จำนวนงานที่ค้างส่งและ Aging เฉลี่ย
A5: Slide 9 | B5: DOC Owner: Sermsiri Bampentam | C5: Sermsiri (IPRAN/TME) | F5: =AVERAGEIF('2026'!S:S, "Sermsiri Bampentam",'2026'!BE:BE) -> 14 | G5: เจาะลึกงาน IPRAN/TME
A6: Slide 9 | B6: DOC Owner: Apichart Kampuang | C6: Apichart (MBB/HAE) | F6: =AVERAGEIF('2026'!S:S, "Apichart Kampuang",'2026'!BE:BE) -> 5.7586207 | G6: ภาพรวมงาน MBB/HAE
A7: Slide 10 | B7: Acceptance AC#1 Performance | C7: AC#1 (JAN-DEC) | D7: ='2026'!AB2*0.7 -> 3694342 | E7: ='2026'!BH2 -> 3385456.3 | F7: =AVERAGE('2026'!BJ4:BJ258) -> 14.301653
A8: Slide 10 | B8: Acceptance AC#2 Performance | C8: AC#2 (JAN-DEC) | D8: ='2026'!AB2*0.3 -> 1583289.4 | E8: ='2026'!BK2 -> 782067.08 | F8: =AVERAGE('2026'!BM4:BM258) -> 58.412037
A9: Slide 11 | B9: Work Type Analysis | C9: MBB vs IPRAN | G9: เปรียบเทียบความคล่องตัวในการปิดเอกสาร

Sheet Part 4 - Financials
A1: Slide No | B1: Slide Title | C1: Metric | D1: Value (THB) | E1: Notes
A2: Slide 12 | B2: Financial Health Overview | C2: Estimate Final Income | D2: ='2026'!AB2 -> 5277631.4 | E2: ภาพรวมรายได้ประมาณการ
A3: Slide 12 | B3: AR vs AP (Economic Efficiency) | C3: AR (Commerce) | D3: ='2026'!AR2 -> 1916244.1 | E3: วิเคราะห์ส่วนต่าง (Margin)
A4: Slide 12 | B4: AR vs AP (Economic Efficiency) | C4: AP (Payment) | D4: ='2026'!AS2 -> 540628.5 | E4: สถานะการเบิกจ่าย Subcontractors
A5: Slide 12 | B5: Unfulfilled Revenue (Remain) | C5: Remain to Claim | D5: =D2-(D3+D4) -> 2820758.8 | E5: เม็ดเงินที่หายไปชั่วคราว
A6: Slide 13 | B6: Backlog Backlog Week 35 VS Backlog Week 36 | C6: Backlog Week 35 | D6: =Sheet1!N10 -> 1529546.1 | E6: เปรียบเทียบเป้าหมายการเก็บเงินระหว่างสัปดาห์
A7: Slide 13 | B7: Backlog Backlog Week 35 VS Backlog Week 36 | C7: Backlog Week 36 | D7: =Sheet1!N20 -> 1362832.1 | E7: กราฟเส้นแนวโน้มยอดคงค้าง
A8: Slide 14 | B8: Actual Acceptance WK32 | C8: Actual Acceptance WK32 | D8: 200182.15 | E8: ยอด Actual Acceptance WK32
A9: Slide 14 | B9: Actual Acceptance WK33 | C9: Actual Acceptance WK33 | D9: 574611.8 | E9: ยอด Actual Acceptance WK33
A10: Slide 14 | B10: Actual Acceptance WK34 | C10: Actual Acceptance WK34 | D10: 321841.3 | E10: ยอด Actual Acceptance WK34
A11: Slide 14 | B11: Actual Acceptance WK35 | C11: Actual Acceptance WK35 | D11: 390171.6 | E11: ยอด Actual Acceptance WK35
A12: Slide 14 | B12: Actual Acceptance WK36 | C12: Actual Acceptance WK36 | D12: 346396.4 | E12: ยอด Actual Acceptance WK36
A13: Slide 15 | B13: Actual Acceptance TOTAL (JAN-AUGUST) HUAWEI | C13: Actual Acceptance TOTAL (JAN-AUGUST) HUAWEI | D13: 6126104.7 | E13: ยอด Actual Actual Acceptance TOTAL (JAN-AUGUST) HUAWEI
A14: Slide 15 | B14: Actual Acceptance TOTAL (JAN-AUGUST) TRUE-TUC | C14: Actual Acceptance TOTAL (JAN-AUGUST) TRUE-TUC | D14: 6982082.2 | E14: ยอด Actual Actual Acceptance TOTAL (JAN-AUGUST) TRUE-TUC
A15: Slide 16 | B15: Plan: Action Plan AC#1 WK36 | C15: Action Plan AC#1 WK36 | D15: 182483 | E15: Action Plan AC#1 WK35
A16: Slide 16 | B16: Plan: Action Plan AC#2 WK36 | C16: Action Plan AC#2 WK36 | D16: 139847.4 | E16: Action Plan AC#2 WK35
A17: Slide 16 | B17: Plan: Action Plan TOTAL WK36 | C17: Action Plan TOTAL WK36 | D17: =SUM(D15:D16) -> 322330.4 | E17: Action Plan TOTAL WK35
A18: Slide 17 | B18: Plan: Acceptance AC#1 Plan WK36 (2023) | C18: Action Plan AC#1 WK36 | D18: =Sheet1!R27 -> 0 | E18: ยอด Remain ที่ตั้งเป้าจะเคลียร์ (2023)
A19: Slide 17 | B19: Plan: Acceptance AC#1 Plan WK36 (2024) | C19: Action Plan AC#1 WK36 | D19: =Sheet1!R28 -> 0 | E19: ยอด Remain ที่ตั้งเป้าจะเคลียร์ (2024)
A20: Slide 17 | B20: Plan: Acceptance AC#1 Plan WK36 (2025) | C20: Action Plan AC#1 WK36 | D20: =Sheet1!R29 -> 0 | E20: ยอด Remain ที่ตั้งเป้าจะเคลียร์ (2025)
A21: Slide 17 | B21: Plan: Acceptance AC#1 Plan WK36 (2026) | C21: Action Plan AC#1 WK36 | D21: 85350.3 | E21: ยอด Remain ที่ตั้งเป้าจะเคลียร์ (2026)
A22: Slide 17 | B22: Plan: Acceptance AC#1 Plan WK36 (TOTAL) | C22: Action Plan AC#1 WK 36 TOTAL | D22: =SUM(D18:D21) -> 85350.3 | E22: ยอด Remain Plan AC#1 WK 30 Total Amount
A23: Slide 18 | B23: Plan: Acceptance AC#2 Plan WK36 (2023) | C23: Action Plan AC#2 WK36 | D23: =Sheet1!R32 -> 0 | E23: ยอด Remain ที่ตั้งเป้าจะเคลียร์ (2023)
A24: Slide 18 | B24: Plan: Acceptance AC#2 Plan WK36 (2024) | C24: Action Plan AC#2 WK36 | D24: =Sheet1!R33 -> 0 | E24: ยอด Remain ที่ตั้งเป้าจะเคลียร์ (2024)
A25: Slide 18 | B25: Plan: Acceptance AC#2 Plan WK36 (2025) | C25: Action Plan AC#2 WK36 | E25: ยอด Remain ที่ตั้งเป้าจะเคลียร์ (2025)
A26: Slide 18 | B26: Plan: Acceptance AC#2 Plan WK36 (2026) | C26: Action Plan AC#2 WK36 | D26: 68127.6 | E26: ยอด Remain ที่ตั้งเป้าจะเคลียร์ (2026)
A27: Slide 18 | B27: Plan: Acceptance AC#2 Plan WK36 (TOTAL) | C27: Action Plan AC#2 WK36 TOTAL | D27: =SUM(D23:D26) -> 68127.6 | E27: แผนผลักดัน Plan AC#2 WK30 Total Amount
A28: Slide 19 | B28: Recovery Plan: Install On-Process | C28: On-Process (2026) TME-MBB | D28: =SUMIF('2026'!BP:BP,'Part 4 - Financials'!F28&'Part 4 - Financials'!G28,'2026'!AB:AB) -> 501518 | E28: มูลค่างานที่อยู่ระหว่างดำเนินการ | F28: TME | G28: MBB
A29: Slide 19 | B29: Recovery Plan: Install On-Process | C29: On-Process (2026) TME-IPRAN | D29: =SUMIF('2026'!BP:BP,'Part 4 - Financials'!F29&'Part 4 - Financials'!G29,'2026'!AB:AB) -> 225486.4 | E29: มูลค่างานที่อยู่ระหว่างดำเนินการ | F29: TME | G29: IPRAN
A30: Slide 19 | B30: Recovery Plan: Install On-Process | C30: On-Process (2026) TME-BATTERY | D30: =SUMIF('2026'!BP:BP,'Part 4 - Financials'!F30&'Part 4 - Financials'!G30,'2026'!AB:AB) -> 10214 | E30: มูลค่างานที่อยู่ระหว่างดำเนินการ | F30: TME | G30: BATERRY
A31: Slide 19 | B31: Recovery Plan: Install On-Process | C31: On-Process (2026) HAE-MBB | D31: =SUMIF('2026'!BP:BP,'Part 4 - Financials'!F31&'Part 4 - Financials'!G31,'2026'!AB:AB) -> 4540413 | E31: มูลค่างานที่อยู่ระหว่างดำเนินการ | F31: HAE | G31: MBB
A32: Slide 19 | B32: Recovery Plan: Install On-Process | C32: On-Process (2026) TRE-DISMANTLE | D32: =SUMIF('2026'!BP:BP,'Part 4 - Financials'!F32&'Part 4 - Financials'!G32,'2026'!AB:AB) -> 0 | E32: มูลค่างานที่อยู่ระหว่างดำเนินการ | F32: TRE | G32: DISMANTLE
A33: Slide 20 | B33: AC1 DONE (2023) REMAIN | C33: AC1 DONE REMAIN/ Total | D33: =Sheet1!E16 -> 25739.04 | E33: ยอด Remain ที่ตั้งเป้าจะเคลียร์ (2023)
A34: Slide 20 | B34: AC1 DONE (2024) REMAIN | C34: AC1 DONE REMAIN/ Total | D34: =Sheet1!E17 -> 7724.43 | E34: ยอด Remain ที่ตั้งเป้าจะเคลียร์ (2024)
A35: Slide 20 | B35: AC1 DONE (2025) REMAIN | C35: AC1 DONE REMAIN/ Total | D35: =Sheet1!E18 -> 27600 | E35: ยอด Remain ที่ตั้งเป้าจะเคลียร์ (2025)
A36: Slide 20 | B36: AC1 DONE (2026) REMAIN | C36: AC1 DONE REMAIN/ Total | D36: =Sheet1!E19 -> 142200.5 | E36: ยอด Remain ที่ตั้งเป้าจะเคลียร์ (2026)
A37: Slide 20 | B37: UNFULFILL (2023) REMAIN | C37: UNFULFILL REMAIN / Total | D37: =Sheet1!K16 -> 112782 | E37: ยอด Remain ที่ตั้งเป้าจะเคลียร์ (2023)
A38: Slide 20 | B38: UNFULFILL (2024) REMAIN | C38: UNFULFILL REMAIN / Total | D38: =Sheet1!K17 -> 60400 | E38: ยอด Remain ที่ตั้งเป้าจะเคลียร์ (2024)
A39: Slide 20 | B39: UNFULFILL (2025) REMAIN | C39: UNFULFILL REMAIN / Total | D39: =Sheet1!K18 -> 57762 | E39: ยอด Remain ที่ตั้งเป้าจะเคลียร์ (2025)
A40: Slide 20 | B40: UNFULFILL (2026) REMAIN | C40: UNFULFILL REMAIN / Total | D40: =Sheet1!K19 -> 768097 | E40: ยอด Remain ที่ตั้งเป้าจะเคลียร์ (2026)
...

Sheet Part 5 - Safety
A1: Slide No | B1: Slide Title | C1: Topic / Metric | E1: Status / Detail

Sheet Part 7 - SLA On-Process AIS
A1: EXECUTIVE SUMMARY: SMART QC | E1: EXECUTIVE SUMMARY: PAT SUBCON SUBMIT
A2: สถานะงาน | B2: จำนวนไซต์ | C2: Aging เฉลี่ย (วัน) | E2: สถานะงาน | F2: จำนวนไซต์ | G2: Aging เฉลี่ย (วัน)
A3: 🟢 ปิดตามกำหนด (Done in SLA) | B3: 136 | C3: 1 | E3: 🟢 ส่งตามกำหนด (Done in SLA) | F3: 119 | G3: 3.2
A4: 🟡 ปิดงานล่าช้า (Done Late) | B4: 63 | C4: 6.7 | E4: 🟡 ส่งงานล่าช้า (Done Late) | F4: 80 | G4: 10.7
A5: 🔵 รอตรวจสอบ (Pending in SLA) | B5: 0 | C5: 0 | E5: 🔵 รอส่งงาน (Pending in SLA) | F5: 0 | G5: 0
A6: 🔴 ปิดเกินกำหนด / ค้างวิกฤต (Over SLA) | B6: 0 | C6: 0 | E6: 🔴 ปิดเกินกำหนด / ค้างวิกฤต (Over SLA) | F6: 0 | G6: 0
A22: ACTION REQUIRED: SMART QC | E22: ACTION REQUIRED: PAT SUBCON | G22: OWNER DOC | I22: REWORK REQUIRED: PAT NOT PASS | K22: OWNER DOC
A23: Site DUID | B23: Aging | E23: Site DUID | F23: Aging | G23: Assign | I23: Site DUID | J23: Aging | K23: Assign
A24: All sites are up to date 🎉 | E24: All sites are up to date 🎉 | G24: - | I24: PKFAM_2026 Capacity Expansion Ph1_EXP_ER | J24: 15 วัน | K24: น.ส. วราพร วงค์พิพันธ์
I25: NKNVM_2026 Capacity Expansion Modernize_EXP_ER | J25: 1 วัน | K25: Apichart Kampuang
I26: NVPSM_2026 Capacity Expansion Modernize_EXP_ER | J26: 1 วัน | K26: Apichart Kampuang
I27: NYOAM_2026 Capacity Expansion Modernize_EXP_ER | J27: 1 วัน | K27: Apichart Kampuang
I28: PMCDM_2026 Capacity Expansion Modernize_EXP_ER | J28: 1 วัน | K28: Apichart Kampuang
I29: SPOCM_2026 Capacity Expansion Modernize_EXP_ER | J29: 2 วัน | K29: น.ส. หทัยรัตน์ สิงห์แก้ว
I30: LPCTM_2026 Capacity Expansion Modernize_EXP_ER | J30: 1 วัน | K30: Apichart Kampuang
I31: TBKBM_2026 Capacity Expansion Modernize_EXP_ER | J31: 2 วัน | K31: น.ส. หทัยรัตน์ สิงห์แก้ว

Sheet Part 7 - SLA On-Process TRUE
A1: EXECUTIVE SUMMARY: SMART QC | E1: EXECUTIVE SUMMARY: PAT SUBCON SUBMIT
A2: สถานะงาน | B2: จำนวนไซต์ | C2: Aging เฉลี่ย (วัน) | E2: สถานะงาน | F2: จำนวนไซต์ | G2: Aging เฉลี่ย (วัน)
A3: 🟢 ปิดตามกำหนด (Done in SLA) | B3: 9 | C3: 1.1 | E3: 🟢 ส่งตามกำหนด (Done in SLA) | F3: 14 | G3: 2.1
A4: 🟡 ปิดงานล่าช้า (Done Late) | B4: 8 | C4: 9.1 | E4: 🟡 ส่งงานล่าช้า (Done Late) | F4: 2 | G4: 8.5
A5: 🔵 รอตรวจสอบ (Pending in SLA) | B5: 1 | C5: 1 | E5: 🔵 รอส่งงาน (Pending in SLA) | F5: 1 | G5: 4
A6: 🔴 ปิดเกินกำหนด / ค้างวิกฤต (Over SLA) | B6: 0 | C6: 0 | E6: 🔴 ปิดเกินกำหนด / ค้างวิกฤต (Over SLA) | F6: 0 | G6: 0
A22: ACTION REQUIRED: SMART QC | E22: ACTION REQUIRED: PAT SUBCON | G22: OWNER DOC | I22: REWORK REQUIRED: ALARM FOUND | K22: OWNER DOC
A23: Site DUID | B23: Aging | E23: Site DUID | F23: Aging | G23: Assign | I23: Site DUID | J23: Aging | K23: Assign
A24: CBR1005_Flash_RAN_EAS R3 | B24: 1 วัน | E24: CBR7972_Flash_RAN_EAS R3 | F24: 4 วัน | G24: GSC HW | I24: No rework required 🎉 | K24: -

Sheet 2026
A1: PM | B1: PM | C1: PM | D1: PM | E1: PM | F1: PM | G1: PM | H1: PM | I1: PM | J1: PM | K1: PM | L1: PM | M1: PM | O1: PM | P1: PM | Q1: PM | R1: PM | S1: PM | T1: PM | U1: PM | V1: PM | W1: PM | X1: PM | Y1: PM | Z1: PM | AA1: PM | AB1: PM | AC1: PM | AD1: CPO | AE1: CPO | AF1: CPO | AG1: CPO | AH1: CPO | AI1: CPO | AJ1: CPO | AK1: CPO | AL1: CPO | AM1: CPO | AN1: CPO | AO1: CPO | AP1: CPO | AQ1: CPO | AR1: ACCOUNT | AS1: ACCOUNT | AT1: PM | AU1: PM | AV1: PM | AW1: PM | AX1: CPO | AY1: CPO | AZ1: CPO | BA1: CPO
A2: 321 | B2: 324 | C2: 324 | D2: 4177505.1 | E2: 5109575.4 | F2: 324 | G2: 324 | H2: 324 | I2: 324 | J2: 324 | K2: 324 | L2: 299 | M2: 298 | O2: 299 | P2: 299 | Q2: 299 | R2: 298 | S2: 297 | T2: 322 | U2: 177503 | V2: 3895855.4 | W2: 113980 | X2: 854220 | Y2: 5041558.4 | Z2: 236073 | AA2: 313 | AB2: 5277631.4 | AC2: 3289682.9 | AD2: 798466.12 | AE2: 1123786.1 | AF2: 37800 | AG2: 3000 | AH2: 233 | AI2: 233 | AJ2: 233 | AK2: 1930 | AL2: 2053294.4 | AM2: 1422927.5 | AN2: 266045.24 | AO2: 1688972.8 | AP2: 453866.5 | AQ2: 458068.7 | AR2: 1916244.1 | AS2: 540628.5 | AT2: 175871.77 | AU2: 297 | AV2: 295 | AW2: 320 | AX2: 0 | AY2: 0 | BA2: 0 | BH2: 3385456.3 | BK2: 782067.08 | BN2: 4167523.4 | BO2: 1113252
A3: WON CODE | B3: WON NAME | C3: SITE/DUID | D3: Estimate Plan | E3: Estimate income | F3: Period WON | G3: Project | H3: Phase | I3: Site | J3: PMOwner | K3: Region | L3: Installation | M3: On-Service | N3: MONTH | O3: Subcon | P3: Subcon Account | Q3: TYPE SUB | R3: PE Owner | S3: DOC Owner | T3: WK NUM | U3: SO Survey | V3: SO Service | W3: SO Material | X3: SO Logistics | Y3: SUM SO | Z3: ADDITIONAL WORK | AA3: VO Submit Date | AB3: ESTIMATE FINAL INCOME | AC3: DLPlan | AD3: DLPRPO | AE3: SERVICE | AF3: DOC | AG3: OTHER | AH3: DL END Y/N/OTHER | AI3: PR END Y/N | AJ3: PO END Y/N | AK3: CREDIT NOTE | AL3: SO GGD | AM3: SO AC1 | AN3: SO AC2 | AO3: SO SAP | AP3: PR SUM | AQ3: PO APPROVED | AR3: AR | AS3: AP | AT3: GR INHOUSE | AU3: 1st Milestone | AV3: 2nd Milestone | AW3: 3rd Milestone | AX3: ACCRUE REV | AY3: ACCRUE DL | AZ3: CUSTOMER | BA3: CHECK | BB3: REMARK | BC3: SAP CODE | BD3: AGING 1st Milestone | BE3: AGING 2nd Milestone | BF3: STATUS WORK | BG3: WORK TYPE | BH3: Accaptance AC#1 AMOUNT | BI3: Accaptance AC#1 DONE | BJ3: AGING#1 | BK3: Accaptance AC#2 AMOUNT | BL3: Accaptance AC#2 DONE | BM3: AGING#2 | BN3: SUM AMOUT | BO3: REMAIN
A4: 29753 | B4: HAE-Cap_Q126-TBKDM | C4: TBKDM_2025 Capacity Expansion Ph8_EXP_ER | D4: 14999.6 | E4: 18293 | F4: 46023 | G4: HAE | H4: Cap_Q126 | I4: TBKDM | J4: BOONCHOT BORIWUT | K4: ER | L4: 46041 | M4: 46041 | N4: 46041 | O4: INHOUSE Adirek Kong-ang | P4: - | Q4: INHOUSE | R4: Adisak Chanmao | S4: น.ส. หทัยรัตน์ สิงห์แก้ว | T4: 26WK4 | U4: 793 | V4: 10758 | W4: 2579 | X4: 4163 | Y4: 18293 | Z4: 0 | AA4: - | AB4: 18293 | AC4: 30477.6 | AD4: 300 | AE4: 300 | AF4: 300 | AG4: 0 | AH4: Y | AI4: Y | AJ4: Y | AK4: 0 | AL4: 18293 | AM4: 15065.6 | AN4: 3227.4 | AO4: 18293 | AP4: 300 | AQ4: 300 | AR4: 18293 | AS4: 300 | AT4: 1352 | AU4: 46046 | AV4: 46050 | AW4: - | AX4: 0 | AY4: 0 | AZ4: HUAWEI | BD4: 5 | BE4: 9 | BF4: COMPLETED | BG4: MBB | BH4: 15065.6 | BI4: 46055 | BJ4: 14 | BK4: 3227.4 | BL4: 46081 | BM4: 40 | BN4: 18293 | BO4: 0 | BP4: =G4&BG4 -> HAEMBB
A5: 29754 | B5: HAE-Cap_Q126-TLRPM | C5: TLRPM_2025 Capacity Expansion Ph8_EXP_ER | D5: 10631.2 | E5: 12966 | F5: 46023 | G5: HAE | H5: Cap_Q126 | I5: TLRPM | J5: BOONCHOT BORIWUT | K5: ER | L5: 46041 | M5: 46041 | N5: 46041 | O5: INHOUSE PHET SAITHONG | P5: - | Q5: INHOUSE | R5: Adisak Chanmao | S5: Adisak Chanmao | T5: 26WK4 | U5: 793 | V5: 8008 | W5: 2579 | X5: 1586 | Y5: 12966 | Z5: 4453 | AA5: 46076 | AB5: 17419 | AC5: 30477.6 | AD5: 300 | AE5: 300 | AF5: 300 | AG5: 0 | AH5: Y | AI5: Y | AJ5: Y | AK5: 0 | AL5: 20062 | AM5: 16496.4 | AN5: 3036.6 | AO5: 19533 | AP5: 300 | AQ5: 300 | AR5: 19533 | AS5: 300 | AT5: 1352 | AU5: 46044 | AV5: 46050 | AW5: - | AX5: 529 | AY5: 0 | AZ5: HUAWEI | BD5: 3 | BE5: 9 | BF5: COMPLETED | BG5: MBB | BH5: 16866.7 | BI5: 46055 | BJ5: 14 | BK5: 3195.3 | BL5: 46081 | BM5: 40 | BN5: 20062 | BO5: 0 | BP5: =G5&BG5 -> HAEMBB
A6: 29762 | B6: HAE-Cap_Q126-CPCEM | C6: CPCEM_2025 Capacity Expansion Ph8_EXP_ER | D6: 11391.4 | E6: 13892 | F6: 46023 | G6: HAE | H6: Cap_Q126 | I6: CPCEM | J6: BOONCHOT BORIWUT | K6: ER | L6: 46039 | M6: 46039 | N6: 46039 | O6: INHOUSE Adirek Kong-ang | P6: - | Q6: INHOUSE | R6: Adisak Chanmao | S6: น.ส. หทัยรัตน์ สิงห์แก้ว | T6: 26WK3 | U6: 793 | V6: 8934 | W6: 2579 | X6: 1586 | Y6: 13892 | Z6: 0 | AA6: - | AB6: 13892 | AC6: 30477.6 | AD6: 300 | AE6: 300 | AF6: 300 | AG6: 0 | AH6: Y | AI6: Y | AJ6: Y | AK6: 0 | AL6: 13892 | AM6: 11211.8 | AN6: 2680.2 | AO6: 13892 | AP6: 300 | AQ6: 300 | AR6: 13892 | AS6: 300 | AT6: 1352 | AU6: 46039 | AV6: 46043 | AW6: - | AX6: 0 | AY6: 0 | AZ6: HUAWEI | BD6: 0 | BE6: 4 | BF6: COMPLETED | BG6: MBB | BH6: 11211.8 | BI6: 46055 | BJ6: 16 | BK6: 2680.2 | BL6: 46081 | BM6: 42 | BN6: 13892 | BO6: 0 | BP6: =G6&BG6 -> HAEMBB
A7: 29763 | B7: HAE-Cap_Q126-WSNIM | C7: WSNIM_2025 Capacity Expansion Ph8_EXP_ER | D7: 19812.4 | E7: 24162 | F7: 46023 | G7: HAE | H7: Cap_Q126 | I7: WSNIM | J7: BOONCHOT BORIWUT | K7: ER | L7: 46038 | M7: 46038 | N7: 46038 | O7: นาย อภิชาติ ฟังสันเทียะ | P7: VD00235 | Q7: SUBCON | R7: Adisak Chanmao | S7: น.ส. หทัยรัตน์ สิงห์แก้ว | T7: 26WK3 | U7: 793 | V7: 16627 | W7: 2579 | X7: 4163 | Y7: 24162 | Z7: 4453 | AA7: 46051 | AB7: 28615 | AC7: 30477.6 | AD7: 11925 | AE7: 11625 | AF7: 300 | AG7: 0 | AH7: Y | AI7: Y | AJ7: Y | AK7: 0 | AL7: 31258 | AM7: 25477 | AN7: 5781 | AO7: 31258 | AP7: 11985 | AQ7: 11865 | AR7: 31258 | AS7: 11865 | AT7: 0 | AU7: 46039 | AV7: 46065 | AW7: - | AX7: 0 | AY7: 60 | AZ7: HUAWEI | BD7: 1 | BE7: 27 | BF7: COMPLETED | BG7: MBB | BH7: 25477 | BI7: 46055 | BJ7: 17 | BK7: 5781 | BL7: 46096 | BM7: 58 | BN7: 31258 | BO7: 0 | BP7: =G7&BG7 -> HAEMBB
A8: 29767 | B8: HAE-Cap_Q126-WNALM | C8: WNALM_2025 Capacity Expansion Ph8_EXP_ER | D8: 20809.8 | E8: 25379 | F8: 46023 | G8: HAE | H8: Cap_Q126 | I8: WNALM | J8: BOONCHOT BORIWUT | K8: ER | L8: 46041 | M8: 46041 | N8: 46041 | O8: นาย อภิชาติ ฟังสันเทียะ | P8: VD00235 | Q8: SUBCON | R8: Adisak Chanmao | S8: น.ส. หทัยรัตน์ สิงห์แก้ว | T8: 26WK4 | U8: 793 | V8: 17844 | W8: 2579 | X8: 4163 | Y8: 25379 | Z8: 792 | AA8: 46051 | AB8: 26171 | AC8: 30477.6 | AD8: 12235 | AE8: 11935 | AF8: 300 | AG8: 0 | AH8: Y | AI8: Y | AJ8: Y | AK8: 0 | AL8: 26171 | AM8: 20580.2 | AN8: 5590.8 | AO8: 26171 | AP8: 12235 | AQ8: 12235 | AR8: 26171 | AS8: 12235 | AT8: 0 | AU8: 46042 | AV8: 46045 | AW8: - | AX8: 0 | AY8: 0 | AZ8: HUAWEI | BD8: 1 | BE8: 4 | BF8: COMPLETED | BG8: MBB | BH8: 20580.2 | BI8: 46055 | BJ8: 14 | BK8: 5590.8 | BL8: 46081 | BM8: 40 | BN8: 26171 | BO8: 0 | BP8: =G8&BG8 -> HAEMBB
A9: 29725 | B9: HAE-Cap_Q425-WHCSM | C9: WHCSM_2024 Coverage Expansion ph.2_New Site-Relocate_ER | D9: 47237.74 | E9: 57607 | F9: 46023 | G9: HAE | H9: Cap_Q425 | I9: WHCSM | J9: BOONCHOT BORIWUT | K9: ER | L9: 46043 | M9: 46045 | N9: 46045 | O9: นาย อภิชาติ ฟังสันเทียะ | P9: VD00235 | Q9: SUBCON | R9: Adisak Chanmao | S9: น.ส. หทัยรัตน์ สิงห์แก้ว | T9: 26WK4 | U9: 793 | V9: 44914 | W9: 7737 | X9: 4163 | Y9: 57607 | Z9: 0 | AA9: - | AB9: 57607 | AC9: 35716.34 | AD9: 22685 | AE9: 22385 | AF9: 300 | AG9: 0 | AH9: Y | AI9: Y | AJ9: Y | AK9: 0 | AL9: 52955 | AM9: 40876.4 | AN9: 12078.6 | AO9: 52955 | AP9: 22685 | AQ9: 22685 | AR9: 52955 | AS9: 22685 | AT9: 0 | AU9: 46063 | AV9: 46068 | AW9: - | AX9: 0 | AY9: 0 | AZ9: HUAWEI | BD9: 18 | BE9: 23 | BF9: COMPLETED | BG9: MBB | BH9: 40876.4 | BI9: 46067 | BJ9: 22 | BK9: 12078.6 | BL9: 46087 | BM9: 42 | BN9: 52955 | BO9: 4652 | BP9: =G9&BG9 -> HAEMBB
A10: 29757 | B10: HAE-Cap_Q126-TLBIM | C10: TLBIM_2025 Capacity Expansion Ph8_EXP_ER | D10: 15368.6 | E10: 18743 | F10: 46023 | G10: HAE | H10: Cap_Q126 | I10: TLBIM | J10: BOONCHOT BORIWUT | K10: ER | L10: 46044 | M10: 46044 | N10: 46044 | O10: นาย อภิชาติ ฟังสันเทียะ | P10: VD00235 | Q10: SUBCON | R10: Adisak Chanmao | S10: น.ส. หทัยรัตน์ สิงห์แก้ว | T10: 26WK4 | U10: 793 | V10: 11208 | W10: 2579 | X10: 4163 | Y10: 18743 | Z10: 0 | AA10: - | AB10: 18743 | AC10: 11620.66 | AD10: 8040 | AE10: 7740 | AF10: 300 | AG10: 0 | AH10: Y | AI10: Y | AJ10: Y | AK10: 0 | AL10: 18743 | AM10: 15380.6 | AN10: 3362.4 | AO10: 18743 | AP10: 8040 | AQ10: 8040 | AR10: 18743 | AS10: 8040 | AT10: 0 | AU10: 46044 | AV10: 46048 | AW10: - | AX10: 0 | AY10: 0 | AZ10: HUAWEI | BD10: 0 | BE10: 4 | BF10: COMPLETED | BG10: MBB | BH10: 15380.6 | BI10: 46055 | BJ10: 11 | BK10: 3362.4 | BL10: 46081 | BM10: 37 | BN10: 18743 | BO10: 0 | BP10: =G10&BG10 -> HAEMBB
A11: 29758 | B11: HAE-Cap_Q126-KNBPM | C11: KNBPM_2025 Capacity Expansion Ph8_EXP_ER | D11: 22933.8 | E11: 27969 | F11: 46023 | G11: HAE | H11: Cap_Q126 | I11: KNBPM | J11: BOONCHOT BORIWUT | K11: ER | L11: 46047 | M11: 46048 | N11: 46048 | O11: นาย อภิชาติ ฟังสันเทียะ | P11: VD00235 | Q11: SUBCON | R11: Adisak Chanmao | S11: น.ส. หทัยรัตน์ สิงห์แก้ว | T11: 26WK5 | U11: 793 | V11: 20434 | W11: 2579 | X11: 4163 | Y11: 27969 | Z11: 4453 | AA11: 46076 | AB11: 32422 | AC11: 17340.78 | AD11: 13255 | AE11: 12955 | AF11: 300 | AG11: 0 | AH11: Y | AI11: Y | AJ11: Y | AK11: 0 | AL11: 32422 | AM11: 26291.8 | AN11: 6130.2 | AO11: 32422 | AP11: 13255 | AQ11: 13255 | AR11: 32422 | AS11: 13255 | AT11: 0 | AU11: 46051 | AV11: 46057 | AW11: - | AX11: 0 | AY11: 0 | AZ11: HUAWEI | BD11: 3 | BE11: 9 | BF11: COMPLETED | BG11: MBB | BH11: 26291.8 | BI11: 46061 | BJ11: 13 | BK11: 6130.2 | BL11: 46081 | BM11: 33 | BN11: 32422 | BO11: 0 | BP11: =G11&BG11 -> HAEMBB
A12: 29759 | B12: HAE-Cap_Q126-KPWTM | C12: KPWTM_2025 Capacity Expansion Ph8_EXP_ER | D12: 12961.6 | E12: 15808 | F12: 46023 | G12: HAE | H12: Cap_Q126 | I12: KPWTM | J12: BOONCHOT BORIWUT | K12: ER | L12: 46048 | M12: 46048 | N12: 46048 | O12: INHOUSE Adirek Kong-ang | P12: - | Q12: INHOUSE | R12: Adisak Chanmao | S12: น.ส. หทัยรัตน์ สิงห์แก้ว | T12: 26WK5 | U12: 793 | V12: 8273 | W12: 2579 | X12: 4163 | Y12: 15808 | Z12: 0 | AA12: - | AB12: 15808 | AC12: 9800.96 | AD12: 300 | AE12: 300 | AF12: 300 | AG12: 0 | AH12: Y | AI12: Y | AJ12: Y | AK12: 0 | AL12: 15808 | AM12: 13326.1 | AN12: 2481.9 | AO12: 15808 | AP12: 300 | AQ12: 300 | AR12: 15808 | AS12: 300 | AT12: 1352 | AU12: 46057 | AV12: 46060 | AW12: - | AX12: 0 | AY12: 0 | AZ12: HUAWEI | BD12: 9 | BE12: 12 | BF12: COMPLETED | BG12: MBB | BH12: 13326.1 | BI12: 46067 | BJ12: 19 | BK12: 2481.9 | BL12: 46081 | BM12: 33 | BN12: 15808 | BO12: 0 | BP12: =G12&BG12 -> HAEMBB
A13: 29760 | B13: HAE-Cap_Q126-CPTCM | C13: CPTCM_2025 Capacity Expansion Ph8_EXP_ER | D13: 15802.2 | E13: 19271 | F13: 46023 | G13: HAE | H13: Cap_Q126 | I13: CPTCM | J13: BOONCHOT BORIWUT | K13: ER | L13: 46046 | M13: 46046 | N13: 46046 | O13: INHOUSE PHET SAITHONG | P13: - | Q13: INHOUSE | R13: Adisak Chanmao | S13: น.ส. หทัยรัตน์ สิงห์แก้ว | T13: 26WK4 | U13: 793 | V13: 11736 | W13: 2579 | X13: 4163 | Y13: 19271 | Z13: 4453 | AA13: 46076 | AB13: 23724 | AC13: 11948.02 | AD13: 300 | AE13: 300 | AF13: 300 | AG13: 0 | AH13: Y | AI13: Y | AJ13: Y | AK13: 0 | AL13: 23724 | AM13: 20203.2 | AN13: 3520.8 | AO13: 23724 | AP13: 300 | AQ13: 300 | AR13: 23724 | AS13: 300 | AT13: 1352 | AU13: 46056 | AV13: 46063 | AW13: - | AX13: 0 | AY13: 0 | AZ13: HUAWEI | BD13: 10 | BE13: 17 | BF13: COMPLETED | BG13: MBB | BH13: 20203.2 | BI13: 46067 | BJ13: 21 | BK13: 3520.8 | BL13: 46096 | BM13: 50 | BN13: 23724 | BO13: 0 | BP13: =G13&BG13 -> HAEMBB
A14: 29761 | B14: HAE-Cap_Q126-BKWNM | C14: BKWNM_2025 Capacity Expansion Ph8_EXP_ER | D14: 20810.8 | E14: 25379 | F14: 46023 | G14: HAE | H14: Cap_Q126 | I14: BKWNM | J14: BOONCHOT BORIWUT | K14: ER | L14: 46046 | M14: 46046 | N14: 46046 | O14: นาย อภิชาติ ฟังสันเทียะ | P14: VD00235 | Q14: SUBCON | R14: Adisak Chanmao | S14: น.ส. หทัยรัตน์ สิงห์แก้ว | T14: 26WK4 | U14: 793 | V14: 17844 | W14: 2579 | X14: 4163 | Y14: 25379 | Z14: 0 | AA14: - | AB14: 25379 | AC14: 15734.98 | AD14: 11975 | AE14: 11675 | AF14: 300 | AG14: 0 | AH14: Y | AI14: Y | AJ14: Y | AK14: 0 | AL14: 25379 | AM14: 20025.8 | AN14: 5353.2 | AO14: 25379 | AP14: 11975 | AQ14: 11975 | AR14: 25379 | AS14: 11975 | AT14: 0 | AU14: 46047 | AV14: 46048 | AW14: - | AX14: 0 | AY14: 0 | AZ14: HUAWEI | BD14: 1 | BE14: 2 | BF14: COMPLETED | BG14: MBB | BH14: 20025.8 | BI14: 46055 | BJ14: 9 | BK14: 5353.2 | BL14: 46081 | BM14: 35 | BN14: 25379 | BO14: 0 | BP14: =G14&BG14 -> HAEMBB
A15: 29764 | B15: HAE-Cap_Q126-TTBPM | C15: TTBPM_2025 Capacity Expansion Ph8_EXP_ER | D15: 23694.2 | E15: 28896 | F15: 46023 | G15: HAE | H15: Cap_Q126 | I15: TTBPM | J15: BOONCHOT BORIWUT | K15: ER | L15: 46044 | M15: 46044 | N15: 46044 | O15: INHOUSE Adirek Kong-ang | P15: - | Q15: INHOUSE | R15: Adisak Chanmao | S15: น.ส. หทัยรัตน์ สิงห์แก้ว | T15: 26WK4 | U15: 793 | V15: 21361 | W15: 2579 | X15: 4163 | Y15: 28896 | Z15: 0 | AA15: - | AB15: 28896 | AC15: 17915.52 | AD15: 300 | AE15: 300 | AF15: 300 | AG15: 0 | AH15: Y | AI15: Y | AJ15: Y | AK15: 0 | AL15: 28896 | AM15: 22487.7 | AN15: 6408.3 | AO15: 28896 | AP15: 300 | AQ15: 300 | AR15: 28896 | AS15: 300 | AT15: 1352 | AU15: 46044 | AV15: 46046 | AW15: - | AX15: 0 | AY15: 0 | AZ15: HUAWEI | BD15: 0 | BE15: 2 | BF15: COMPLETED | BG15: MBB | BH15: 22487.7 | BI15: 46055 | BJ15: 11 | BK15: 6408.3 | BL15: 46081 | BM15: 37 | BN15: 28896 | BO15: 0 | BP15: =G15&BG15 -> HAEMBB
A16: 29766 | B16: HAE-Cap_Q126-WPNRM | C16: WPNRM_2025 Capacity Expansion Ph8_EXP_ER | D16: 11607.2 | E16: 14156 | F16: 46023 | G16: HAE | H16: Cap_Q126 | I16: WPNRM | J16: BOONCHOT BORIWUT | K16: ER | L16: 46044 | M16: 46044 | N16: 46044 | O16: INHOUSE PHET SAITHONG | P16: - | Q16: INHOUSE | R16: Adisak Chanmao | S16: น.ส. หทัยรัตน์ สิงห์แก้ว | T16: 26WK4 | U16: 793 | V16: 9198 | W16: 2579 | X16: 1586 | Y16: 14156 | Z16: 8906 | AA16: 46076 | AB16: 23062 | AC16: 8776.72 | AD16: 300 | AE16: 300 | AF16: 300 | AG16: 0 | AH16: Y | AI16: Y | AJ16: Y | AK16: 0 | AL16: 23062 | AM16: 20302.6 | AN16: 2759.4 | AO16: 23062 | AP16: 360 | AQ16: 240 | AR16: 23062 | AS16: 240 | AT16: 1352 | AU16: 46044 | AV16: 46045 | AW16: - | AX16: 0 | AY16: 60 | AZ16: HUAWEI | BD16: 0 | BE16: 1 | BF16: COMPLETED | BG16: MBB | BH16: 20302.6 | BI16: 46055 | BJ16: 11 | BK16: 2759.4 | BL16: 46081 | BM16: 37 | BN16: 23062 | BO16: 0 | BP16: =G16&BG16 -> HAEMBB
A17: 29755 | B17: HAE-Cap_Q126-PNTHM | C17: PNTHM_2025 Capacity Expansion Ph8_EXP_ER | D17: 20744.8 | E17: 25299 | F17: 46023 | G17: HAE | H17: Cap_Q126 | I17: PNTHM | J17: BOONCHOT BORIWUT | K17: ER | L17: 46053 | M17: 46053 | N17: 46053 | O17: INHOUSE Adirek Kong-ang | P17: - | Q17: INHOUSE | R17: Adisak Chanmao | S17: น.ส. หทัยรัตน์ สิงห์แก้ว | T17: 26WK5 | U17: 793 | V17: 17764 | W17: 2579 | X17: 4163 | Y17: 25299 | Z17: 4453 | AA17: 46076 | AB17: 29752 | AC17: 15685.38 | AD17: 300 | AE17: 300 | AF17: 300 | AG17: 0 | AH17: Y | AI17: Y | AJ17: Y | AK17: 0 | AL17: 29752 | AM17: 24422.8 | AN17: 5329.2 | AO17: 29752 | AP17: 300 | AQ17: 300 | AR17: 29752 | AS17: 300 | AT17: 1352 | AU17: 46063 | AV17: 46072 | AW17: - | AX17: 0 | AY17: 0 | AZ17: HUAWEI | BD17: 10 | BE17: 19 | BF17: COMPLETED | BG17: MBB | BH17: 24422.8 | BI17: 46081 | BJ17: 28 | BK17: 5329.2 | BL17: 46096 | BM17: 43 | BN17: 29752 | BO17: 0 | BP17: =G17&BG17 -> HAEMBB
A18: 29765 | B18: HAE-Cap_Q126-WTWAM | C18: WTWAM_2025 Capacity Expansion Ph8_EXP_ER | D18: 19184.2 | E18: 23396 | F18: 46023 | G18: HAE | H18: Cap_Q126 | I18: WTWAM | J18: BOONCHOT BORIWUT | K18: ER | L18: 46055 | M18: 46055 | N18: 46055 | O18: นาย อภิชาติ ฟังสันเทียะ | P18: VD00235 | Q18: SUBCON | R18: Adisak Chanmao | S18: น.ส. หทัยรัตน์ สิงห์แก้ว | T18: 26WK6 | U18: 793 | V18: 15861 | W18: 2579 | X18: 4163 | Y18: 23396 | Z18: 0 | AA18: - | AB18: 23396 | AC18: 14505.52 | AD18: 11555 | AE18: 11255 | AF18: 300 | AG18: 0 | AH18: Y | AI18: Y | AJ18: Y | AK18: 0 | AL18: 23396 | AM18: 18637.7 | AN18: 4758.3 | AO18: 23396 | AP18: 11615 | AQ18: 11495 | AR18: 23396 | AS18: 11495 | AT18: 0 | AU18: 46057 | AV18: 46065 | AW18: - | AX18: 0 | AY18: 60 | AZ18: HUAWEI | BD18: 2 | BE18: 10 | BF18: COMPLETED | BG18: MBB | BH18: 18637.7 | BI18: 46067 | BJ18: 12 | BK18: 4758.3 | BL18: 46096 | BM18: 41 | BN18: 23396 | BO18: 0 | BP18: =G18&BG18 -> HAEMBB
A19: EP26010018 | B19: HAE-NEWSITE-SHTLM | C19: SHTLM_2024 Coverage Expansion ph.2_New Site-Relocate_ER | D19: 22252.34 | E19: 27137 | F19: 46023 | G19: HAE | H19: NEWSITE | I19: SHTLM | J19: BOONCHOT BORIWUT | K19: ER | L19: 46049 | M19: 46053 | N19: 46053 | O19: INHOUSE PHET SAITHONG | P19: - | Q19: INHOUSE | R19: Adisak Chanmao | S19: น.ส. หทัยรัตน์ สิงห์แก้ว | T19: 26WK5 | U19: 793 | V19: 22179 | W19: 2579 | X19: 1586 | Y19: 27137 | Z19: 5024 | AA19: 46076 | AB19: 32161 | AC19: 16824.94 | AD19: 300 | AE19: 0 | AF19: 300 | AG19: 0 | AH19: Y | AI19: Y | AJ19: Y | AK19: 0 | AL19: 32161 | AM19: 6622.6 | AN19: 713.4 | AO19: 7336 | AP19: 300 | AQ19: 300 | AR19: 7336 | AS19: 300 | AT19: 6760 | AU19: 46059 | AV19: 46063 | AW19: - | AX19: 24825 | AY19: 0 | AZ19: HUAWEI | BD19: 6 | BE19: 10 | BF19: COMPLETED | BG19: MBB | BH19: 10139.4 | BI19: 46067 | BJ19: 14 | BK19: 2220.6 | BL19: 46087 | BM19: 34 | BN19: 12360 | BO19: 0 | BP19: =G19&BG19 -> HAEMBB
A20: EP26020021 | B20: TME-DIS_ATN-RYG0118 | C20: RYG0118-AC-02_D_Dismantle_EAST_R3 | D20: 1687.29 | E20: 2081 | F20: 46054 | G20: TME | H20: DIS_ATN | I20: RYG0118 | J20: BOONCHOT BORIWUT | K20: ER | L20: 46051 | M20: 46051 | N20: 46051 | O20: บริษัท สุพรรณ เทเลคอม จำกัด | P20: VD00327 | Q20: SUBCON | R20: Adisak Chanmao | S20: Sermsiri Bampentam | T20: 26WK5 | U20: 0 | V20: 1970 | W20: 0 | X20: 111 | Y20: 2081 | Z20: 0 | AA20: - | AB20: 2081 | AC20: 1500 | AD20: 1230 | AE20: 1230 | AF20: 0 | AG20: 0 | AH20: Y | AI20: Y | AJ20: Y | AK20: 0 | AL20: 2081 | AM20: 1687 | AN20: 0 | AO20: 1687 | AP20: 1230 | AQ20: 1230 | AR20: 1687 | AS20: 1230 | AT20: 0 | AU20: 46051 | AV20: 46065 | AW20: - | AX20: 394 | AY20: 0 | AZ20: HUAWEI | BD20: 0 | BE20: 14 | BF20: COMPLETED | BG20: IPRAN | BH20: 1687 | BI20: 46073 | BJ20: 22 | BK20: 394 | BL20: 46230 | BM20: 179 | BN20: 2081 | BO20: 0 | BP20: =G20&BG20 -> TMEIPRAN
A21: EP26020022 | B21: TME-DIS_ATN-RYG0146 | C21: RYG0146-AC-02_D_Dismantle_EAST_R3 | D21: 1687.29 | E21: 2081 | F21: 46054 | G21: TME | H21: DIS_ATN | I21: RYG0146 | J21: BOONCHOT BORIWUT | K21: ER | L21: 46051 | M21: 46051 | N21: 46051 | O21: บริษัท สุพรรณ เทเลคอม จำกัด | P21: VD00327 | Q21: SUBCON | R21: Adisak Chanmao | S21: Sermsiri Bampentam | T21: 26WK5 | U21: 0 | V21: 1970 | W21: 0 | X21: 111 | Y21: 2081 | Z21: 0 | AA21: - | AB21: 2081 | AC21: 1500 | AD21: 1230 | AE21: 1230 | AF21: 0 | AG21: 0 | AH21: Y | AI21: Y | AJ21: Y | AK21: 0 | AL21: 2081 | AM21: 1687 | AN21: 0 | AO21: 1687 | AP21: 1230 | AQ21: 1230 | AR21: 1687 | AS21: 1230 | AT21: 0 | AU21: 46051 | AV21: 46073 | AW21: - | AX21: 394 | AY21: 0 | AZ21: HUAWEI | BD21: 0 | BE21: 22 | BF21: COMPLETED | BG21: IPRAN | BH21: 1687 | BI21: 46073 | BJ21: 22 | BK21: 394 | BL21: 46230 | BM21: 179 | BN21: 2081 | BO21: 0 | BP21: =G21&BG21 -> TMEIPRAN
A22: EP26020023 | B22: TME-DIS_ATN-RYG0168 | C22: RYG0168-AC-02_D_Dismantle_EAST_R3 | D22: 1687.29 | E22: 2081 | F22: 46054 | G22: TME | H22: DIS_ATN | I22: RYG0168 | J22: BOONCHOT BORIWUT | K22: ER | L22: 46051 | M22: 46051 | N22: 46051 | O22: บริษัท สุพรรณ เทเลคอม จำกัด | P22: VD00327 | Q22: SUBCON | R22: Adisak Chanmao | S22: Sermsiri Bampentam | T22: 26WK5 | U22: 0 | V22: 1970 | W22: 0 | X22: 111 | Y22: 2081 | Z22: 0 | AA22: - | AB22: 2081 | AC22: 1500 | AD22: 1230 | AE22: 1230 | AF22: 0 | AG22: 0 | AH22: Y | AI22: Y | AJ22: Y | AK22: 0 | AL22: 2081 | AM22: 1687 | AN22: 0 | AO22: 1687 | AP22: 1230 | AQ22: 1230 | AR22: 1687 | AS22: 1230 | AT22: 0 | AU22: 46071 | AV22: 46073 | AW22: - | AX22: 394 | AY22: 0 | AZ22: HUAWEI | BD22: 20 | BE22: 22 | BF22: COMPLETED | BG22: IPRAN | BH22: 1687 | BI22: 46081 | BJ22: 30 | BK22: 394 | BL22: 46230 | BM22: 179 | BN22: 2081 | BO22: 0 | BP22: =G22&BG22 -> TMEIPRAN
A23: EP26020024 | B23: TME-DIS_ATN-RYG0083 | C23: RYG0083-AC-02_D_Dismantle_EAST_R3 | D23: 1687.29 | E23: 2081 | F23: 46054 | G23: TME | H23: DIS_ATN | I23: RYG0083 | J23: BOONCHOT BORIWUT | K23: ER | L23: 46052 | M23: 46052 | N23: 46052 | O23: บริษัท สุพรรณ เทเลคอม จำกัด | P23: VD00327 | Q23: SUBCON | R23: Adisak Chanmao | S23: Sermsiri Bampentam | T23: 26WK5 | U23: 0 | V23: 1970 | W23: 0 | X23: 111 | Y23: 2081 | Z23: 0 | AA23: - | AB23: 2081 | AC23: 1500 | AD23: 1230 | AE23: 1230 | AF23: 0 | AG23: 0 | AH23: Y | AI23: Y | AJ23: Y | AK23: 0 | AL23: 2081 | AM23: 1687 | AN23: 0 | AO23: 1687 | AP23: 1230 | AQ23: 1230 | AR23: 1687 | AS23: 1230 | AT23: 0 | AU23: 46052 | AV23: 46065 | AW23: - | AX23: 394 | AY23: 0 | AZ23: HUAWEI | BD23: 0 | BE23: 13 | BF23: COMPLETED | BG23: IPRAN | BH23: 1687 | BI23: 46073 | BJ23: 21 | BK23: 394 | BL23: 46230 | BM23: 178 | BN23: 2081 | BO23: 0 | BP23: =G23&BG23 -> TMEIPRAN
A24: EP26020025 | B24: TME-REPIPRAN-TRT0164 | C24: TRT0164_TRT3001_D_Retain_New_EAST_R3 | D24: 2736.06 | E24: 7468 | F24: 46054 | G24: TME | H24: REPIPRAN | I24: TRT0164 | J24: BOONCHOT BORIWUT | K24: ER | L24: 46052 | M24: 46052 | N24: 46052 | O24: นาย ชัชวาล เคราะห์ดี | P24: VD01205 | Q24: SUBCON | R24: Adisak Chanmao | S24: Sermsiri Bampentam | T24: 26WK5 | U24: 0 | V24: 2364 | W24: 1370 | X24: 0 | Y24: 3734 | Z24: 0 | AA24: - | AB24: 3734 | AC24: 2400 | AD24: 2230 | AE24: 2230 | AF24: 0 | AG24: 0 | AH24: Y | AI24: Y | AJ24: Y | AK24: 0 | AL24: 3734 | AM24: 3261.2 | AN24: 472.8 | AO24: 3734 | AP24: 2230 | AQ24: 2230 | AR24: 3734 | AS24: 1784 | AT24: 0 | AU24: 46051 | AV24: 46162 | AW24: - | AX24: 0 | AY24: 446 | AZ24: HUAWEI | BD24: 0 | BE24: 110 | BF24: COMPLETED | BG24: IPRAN | BH24: 3261.2 | BI24: 46073 | BJ24: 21 | BK24: 472.8 | BL24: 46213 | BM24: 161 | BN24: 3734 | BO24: 0 | BP24: =G24&BG24 -> TMEIPRAN
A25: EP26020026 | B25: TME-REPIPRAN-TRT0135 | C25: TRT0164_TRT0135_D_Retain_New_EAST_R3 | D25: 2736.06 | E25: 3734 | F25: 46054 | G25: TME | H25: REPIPRAN | I25: TRT0135 | J25: BOONCHOT BORIWUT | K25: ER | L25: 46052 | M25: 46052 | N25: 46052 | O25: นาย ชัชวาล เคราะห์ดี | P25: VD01205 | Q25: SUBCON | R25: Adisak Chanmao | S25: Sermsiri Bampentam | T25: 26WK5 | U25: 0 | V25: 2364 | W25: 1370 | X25: 0 | Y25: 3734 | Z25: 0 | AA25: - | AB25: 3734 | AC25: 2400 | AD25: 2230 | AE25: 2230 | AF25: 0 | AG25: 0 | AH25: Y | AI25: Y | AJ25: Y | AK25: 0 | AL25: 3734 | AM25: 3261.2 | AN25: 472.8 | AO25: 3734 | AP25: 2230 | AQ25: 2230 | AR25: 3734 | AS25: 1784 | AT25: 0 | AU25: 46051 | AV25: 46162 | AW25: - | AX25: 0 | AY25: 446 | AZ25: HUAWEI | BD25: 0 | BE25: 110 | BF25: COMPLETED | BG25: IPRAN | BH25: 3261.2 | BI25: 46073 | BJ25: 21 | BK25: 472.8 | BL25: 46213 | BM25: 161 | BN25: 3734 | BO25: 0 | BP25: =G25&BG25 -> TMEIPRAN
A26: EP26020003 | B26: HAE-Cap_Q126-NSCGM | C26: NSCGM_2025 Capacity Expansion Ph8_EXP_ER | D26: 19314.28 | E26: 23554 | F26: 46054 | G26: HAE | H26: Cap_Q126 | I26: NSCGM | J26: BOONCHOT BORIWUT | K26: ER | L26: 46059 | M26: 46059 | N26: 46059 | O26: INHOUSE PHET SAITHONG | P26: - | Q26: INHOUSE | R26: Adisak Chanmao | S26: น.ส. หทัยรัตน์ สิงห์แก้ว | T26: 26WK6 | U26: 793 | V26: 16019 | W26: 2579 | X26: 4163 | Y26: 23554 | Z26: 7535 | AA26: 46076 | AB26: 31089 | AC26: 14603.48 | AD26: 300 | AE26: 300 | AF26: 300 | AG26: 0 | AH26: Y | AI26: Y | AJ26: Y | AK26: 0 | AL26: 31089 | AM26: 26283.3 | AN26: 4805.7 | AO26: 31089 | AP26: 300 | AQ26: 300 | AR26: 31089 | AS26: 300 | AT26: 4710.8 | AU26: 46062 | AV26: 46069 | AW26: - | AX26: 0 | AY26: 0 | AZ26: HUAWEI | BD26: 3 | BE26: 10 | BF26: COMPLETED | BG26: MBB | BH26: 26283.3 | BI26: 46081 | BJ26: 22 | BK26: 4805.7 | BL26: 46096 | BM26: 37 | BN26: 31089 | BO26: 0 | BP26: =G26&BG26 -> HAEMBB
A27: EP26020005 | B27: HAE-Cap_Q126-MKAOM | C27: MKAOM_2025 Capacity Expansion Ph8_EXP_ER | D27: 13363.54 | E27: 16297 | F27: 46054 | G27: HAE | H27: Cap_Q126 | I27: MKAOM | J27: BOONCHOT BORIWUT | K27: ER | L27: 46057 | M27: 46057 | N27: 46057 | O27: นาย อภิชาติ ฟังสันเทียะ | P27: VD00235 | Q27: SUBCON | R27: Adisak Chanmao | S27: น.ส. หทัยรัตน์ สิงห์แก้ว | T27: 26WK6 | U27: 793 | V27: 11339 | W27: 2579 | X27: 1586 | Y27: 16297 | Z27: 792 | AA27: 46076 | AB27: 17089 | AC27: 10104.14 | AD27: 8790 | AE27: 8490 | AF27: 300 | AG27: 0 | AH27: Y | AI27: Y | AJ27: Y | AK27: 1137 | AL27: 17089 | AM27: 13449.7 | AN27: 3639.3 | AO27: 17089 | AP27: 8790 | AQ27: 8790 | AR27: 17089 | AS27: 8790 | AT27: 0 | AU27: 46062 | AV27: 46066 | AW27: - | AX27: 0 | AY27: 0 | AZ27: HUAWEI | BD27: 5 | BE27: 9 | BF27: COMPLETED | BG27: MBB | BH27: 13449.7 | BI27: 46081 | BJ27: 24 | BK27: 3639.3 | BL27: 46096 | BM27: 39 | BN27: 17089 | BO27: 0 | BP27: =G27&BG27 -> HAEMBB
A28: EP26020011 | B28: HAE-Cap_Q126-TPRTM | C28: TPRTM_2025 Capacity Expansion Ph8_EXP_ER | D28: 10481.24 | E28: 12782 | F28: 46054 | G28: HAE | H28: Cap_Q126 | I28: TPRTM | J28: BOONCHOT BORIWUT | K28: ER | L28: 46057 | M28: 46058 | N28: 46058 | O28: INHOUSE PHET SAITHONG | P28: - | Q28: INHOUSE | R28: Adisak Chanmao | S28: น.ส. หทัยรัตน์ สิงห์แก้ว | T28: 26WK6 | U28: 793 | V28: 7824 | W28: 2579 | X28: 1586 | Y28: 12782 | Z28: 1584 | AA28: 46076 | AB28: 14366 | AC28: 7924.84 | AD28: 300 | AE28: 300 | AF28: 300 | AG28: 0 | AH28: Y | AI28: Y | AJ28: Y | AK28: 0 | AL28: 15952 | AM28: 16353.3 | AN28: 4883.7 | AO28: 21237 | AP28: 300 | AQ28: 300 | AR28: 15952 | AS28: 300 | AT28: 2556.4 | AU28: 46068 | AV28: 46073 | AW28: - | AX28: 0 | AY28: 0 | AZ28: HUAWEI | BD28: 10 | BE28: 15 | BF28: COMPLETED | BG28: MBB | BH28: 16353.3 | BI28: 46081 | BJ28: 23 | BK28: 4883.7 | BL28: 46096 | BM28: 38 | BN28: 21237 | BO28: 0 | BP28: =G28&BG28 -> HAEMBB
A29: EP26020012 | B29: HAE-Cap_Q126-SUNGM | C29: SUNGM_2025 Capacity Expansion Ph8_EXP_ER | D29: 20659.08 | E29: 25194 | F29: 46054 | G29: HAE | H29: Cap_Q126 | I29: SUNGM | J29: BOONCHOT BORIWUT | K29: ER | L29: 46056 | M29: 46056 | N29: 46056 | O29: INHOUSE PHET SAITHONG | P29: - | Q29: INHOUSE | R29: Adisak Chanmao | S29: น.ส. หทัยรัตน์ สิงห์แก้ว | T29: 26WK6 | U29: 793 | V29: 17659 | W29: 2579 | X29: 4163 | Y29: 25194 | Z29: 0 | AA29: - | AB29: 25194 | AC29: 15620.28 | AD29: 300 | AE29: 300 | AF29: 300 | AG29: 0 | AH29: Y | AI29: Y | AJ29: Y | AK29: 0 | AL29: 25194 | AM29: 19896.3 | AN29: 5297.7 | AO29: 25194 | AP29: 300 | AQ29: 300 | AR29: 25194 | AS29: 300 | AT29: 5038.8 | AU29: 46064 | AV29: 46069 | AW29: - | AX29: 0 | AY29: 0 | AZ29: HUAWEI | BD29: 8 | BE29: 13 | BF29: COMPLETED | BG29: MBB | BH29: 19896.3 | BI29: 46081 | BJ29: 25 | BK29: 5297.7 | BL29: 46096 | BM29: 40 | BN29: 25194 | BO29: 0 | BP29: =G29&BG29 -> HAEMBB
A30: EP26020014 | B30: HAE-Cap_Q126-DKBKM | C30: DKBKM_2025 Capacity Expansion Ph8_EXP_ER | D30: 13179.04 | E30: 16072 | F30: 46054 | G30: HAE | H30: Cap_Q126 | I30: DKBKM | J30: BOONCHOT BORIWUT | K30: ER | L30: 46059 | M30: 46059 | N30: 46059 | O30: INHOUSE Adirek Kong-ang | P30: - | Q30: INHOUSE | R30: Adisak Chanmao | S30: น.ส. หทัยรัตน์ สิงห์แก้ว | T30: 26WK6 | U30: 793 | V30: 8537 | W30: 2579 | X30: 4163 | Y30: 16072 | Z30: 528 | AA30: 46076 | AB30: 16600 | AC30: 9964.64 | AD30: 300 | AE30: 300 | AF30: 300 | AG30: 0 | AH30: Y | AI30: Y | AJ30: Y | AK30: 0 | AL30: 16600 | AM30: 13880.5 | AN30: 2719.5 | AO30: 16600 | AP30: 360 | AQ30: 240 | AR30: 16600 | AS30: 240 | AT30: 3214.4 | AU30: 46059 | AV30: 46063 | AW30: - | AX30: 0 | AY30: 60 | AZ30: HUAWEI | BD30: 0 | BE30: 4 | BF30: COMPLETED | BG30: MBB | BH30: 13880.5 | BI30: 46067 | BJ30: 8 | BK30: 2719.5 | BL30: 46096 | BM30: 37 | BN30: 16600 | BO30: 0 | BP30: =G30&BG30 -> HAEMBB
A31: EP26020020 | B31: HAE-Cap_Q126-BPGYM | C31: BPGYM_2025 Capacity Expansion Ph8_EXP_ER | D31: 13179.04 | E31: 16072 | F31: 46054 | G31: HAE | H31: Cap_Q126 | I31: BPGYM | J31: BOONCHOT BORIWUT | K31: ER | L31: 46058 | M31: 46058 | N31: 46058 | O31: นาย อภิชาติ ฟังสันเทียะ | P31: VD00235 | Q31: SUBCON | R31: Adisak Chanmao | S31: น.ส. หทัยรัตน์ สิงห์แก้ว | T31: 26WK6 | U31: 793 | V31: 8537 | W31: 2579 | X31: 4163 | Y31: 16072 | Z31: 1056 | AA31: 46076 | AB31: 17128 | AC31: 9964.64 | AD31: 7320 | AE31: 7020 | AF31: 300 | AG31: 0 | AH31: Y | AI31: Y | AJ31: Y | AK31: 0 | AL31: 17128 | AM31: 14250.1 | AN31: 2877.9 | AO31: 17128 | AP31: 7380 | AQ31: 7260 | AR31: 17128 | AS31: 7260 | AT31: 0 | AU31: 46063 | AV31: 46066 | AW31: - | AX31: 0 | AY31: 60 | AZ31: HUAWEI | BD31: 5 | BE31: 8 | BF31: COMPLETED | BG31: MBB | BH31: 14250.1 | BI31: 46081 | BJ31: 23 | BK31: 2877.9 | BL31: 46087 | BM31: 29 | BN31: 17128 | BO31: 0 | BP31: =G31&BG31 -> HAEMBB
A32: EP26020001 | B32: HAE-Cap_Q126-KHASM | C32: KHASM_2025 Capacity Expansion Ph8_EXP_ER | D32: 12810.86 | E32: 15623 | F32: 46066 | G32: HAE | H32: Cap_Q126 | I32: KHASM | J32: BOONCHOT BORIWUT | K32: ER | L32: 46063 | M32: 46063 | N32: 46063 | O32: INHOUSE Adirek Kong-ang | P32: - | Q32: INHOUSE | R32: Adisak Chanmao | S32: น.ส. หทัยรัตน์ สิงห์แก้ว | T32: 26WK7 | U32: 793 | V32: 8088 | W32: 2579 | X32: 4163 | Y32: 15623 | Z32: 1584 | AA32: 46076 | AB32: 17207 | AC32: 9686.26 | AD32: 300 | AE32: 300 | AF32: 300 | AG32: 0 | AH32: Y | AI32: Y | AJ32: Y | AK32: 0 | AL32: 17207 | AM32: 14305.4 | AN32: 2901.6 | AO32: 17207 | AP32: 300 | AQ32: 300 | AR32: 17207 | AS32: 240 | AT32: 3124.6 | AU32: 46072 | AV32: 46077 | AW32: - | AX32: 0 | AY32: 60 | AZ32: HUAWEI | BD32: 9 | BE32: 14 | BF32: COMPLETED | BG32: MBB | BH32: 14305.4 | BI32: 46087 | BJ32: 24 | BK32: 2901.6 | BL32: 46096 | BM32: 33 | BN32: 17207 | BO32: 0 | BP32: =G32&BG32 -> HAEMBB
A33: EP26020004 | B33: HAE-Cap_Q126-RSKBM | C33: RSKBM_2025 Capacity Expansion Ph8_EXP_ER | D33: 9765.38 | E33: 11909 | F33: 46066 | G33: HAE | H33: Cap_Q126 | I33: RSKBM | J33: BOONCHOT BORIWUT | K33: ER | L33: 46065 | M33: 46066 | N33: 46066 | O33: INHOUSE Adirek Kong-ang | P33: - | Q33: INHOUSE | R33: Adisak Chanmao | S33: น.ส. หทัยรัตน์ สิงห์แก้ว | T33: 26WK7 | U33: 793 | V33: 6951 | W33: 2579 | X33: 1586 | Y33: 11909 | Z33: 1452 | AA33: 46076 | AB33: 13361 | AC33: 7383.58 | AD33: 300 | AE33: 300 | AF33: 300 | AG33: 0 | AH33: Y | AI33: Y | AJ33: Y | AK33: 0 | AL33: 13361 | AM33: 10840.1 | AN33: 2520.9 | AO33: 13361 | AP33: 300 | AQ33: 300 | AR33: 13361 | AS33: 300 | AT33: 2381.8 | AU33: 46069 | AV33: 46072 | AW33: - | AX33: 0 | AY33: 0 | AZ33: HUAWEI | BD33: 3 | BE33: 6 | BF33: COMPLETED | BG33: MBB | BH33: 10840.1 | BI33: 46081 | BJ33: 15 | BK33: 2520.9 | BL33: 46087 | BM33: 21 | BN33: 13361 | BO33: 0 | BP33: =G33&BG33 -> HAEMBB
A34: EP26020006 | B34: HAE-Cap_Q126-PTHAM | C34: PTHAM_2025 Capacity Expansion Ph8_EXP_ER | D34: 9765.38 | E34: 11909 | F34: 46066 | G34: HAE | H34: Cap_Q126 | I34: PTHAM | J34: BOONCHOT BORIWUT | K34: ER | L34: 46065 | M34: 46065 | N34: 46065 | O34: INHOUSE Adirek Kong-ang | P34: - | Q34: INHOUSE | R34: Adisak Chanmao | S34: น.ส. หทัยรัตน์ สิงห์แก้ว | T34: 26WK7 | U34: 793 | V34: 6951 | W34: 2579 | X34: 1586 | Y34: 11909 | Z34: 1452 | AA34: 46076 | AB34: 13361 | AC34: 7383.58 | AD34: 300 | AE34: 300 | AF34: 300 | AG34: 0 | AH34: Y | AI34: Y | AJ34: Y | AK34: 0 | AL34: 14498 | AM34: 11636 | AN34: 2862 | AO34: 14498 | AP34: 300 | AQ34: 300 | AR34: 14498 | AS34: 300 | AT34: 2381.8 | AU34: 46066 | AV34: 46069 | AW34: - | AX34: 0 | AY34: 0 | AZ34: HUAWEI | BD34: 1 | BE34: 4 | BF34: COMPLETED | BG34: MBB | BH34: 11636 | BI34: 46081 | BJ34: 16 | BK34: 2862 | BL34: 46087 | BM34: 22 | BN34: 14498 | BO34: 0 | BP34: =G34&BG34 -> HAEMBB
A35: EP26020010 | B35: HAE-Cap_Q126-MBGAM | C35: MBGAM_2025 Capacity Expansion Ph8_EXP_ER | D35: 9765.38 | E35: 11909 | F35: 46066 | G35: HAE | H35: Cap_Q126 | I35: MBGAM | J35: BOONCHOT BORIWUT | K35: ER | L35: 46064 | M35: 46064 | N35: 46064 | O35: INHOUSE PHET SAITHONG | P35: - | Q35: INHOUSE | R35: Adisak Chanmao | S35: น.ส. หทัยรัตน์ สิงห์แก้ว | T35: 26WK7 | U35: 793 | V35: 6951 | W35: 2579 | X35: 1586 | Y35: 11909 | Z35: 396 | AA35: 46076 | AB35: 12305 | AC35: 7383.58 | AD35: 300 | AE35: 300 | AF35: 300 | AG35: 0 | AH35: Y | AI35: Y | AJ35: Y | AK35: 0 | AL35: 12833 | AM35: 10470.5 | AN35: 2362.5 | AO35: 12833 | AP35: 300 | AQ35: 300 | AR35: 12833 | AS35: 300 | AT35: 2381.8 | AU35: 46069 | AV35: 46072 | AW35: - | AX35: 0 | AY35: 0 | AZ35: HUAWEI | BD35: 5 | BE35: 8 | BF35: COMPLETED | BG35: MBB | BH35: 10470.5 | BI35: 46081 | BJ35: 17 | BK35: 2362.5 | BL35: 46096 | BM35: 32 | BN35: 12833 | BO35: 0 | BP35: =G35&BG35 -> HAEMBB
A36: EP26020015 | B36: HAE-Cap_Q126-HAMHM | C36: HAMHM_2025 Capacity Expansion Ph8_EXP_ER | D36: 13179.04 | E36: 16072 | F36: 46066 | G36: HAE | H36: Cap_Q126 | I36: HAMHM | J36: BOONCHOT BORIWUT | K36: ER | L36: 46067 | M36: 46067 | N36: 46067 | O36: INHOUSE Adirek Kong-ang | P36: - | Q36: INHOUSE | R36: Adisak Chanmao | S36: น.ส. หทัยรัตน์ สิงห์แก้ว | T36: 26WK7 | U36: 793 | V36: 8537 | W36: 2579 | X36: 4163 | Y36: 16072 | Z36: 1452 | AA36: 46076 | AB36: 17524 | AC36: 9964.64 | AD36: 300 | AE36: 300 | AF36: 300 | AG36: 0 | AH36: Y | AI36: Y | AJ36: Y | AK36: 0 | AL36: 16996 | AM36: 14157.7 | AN36: 2838.3 | AO36: 16996 | AP36: 540 | AQ36: 60 | AR36: 16996 | AS36: 60 | AT36: 3214.4 | AU36: 46068 | AV36: 46070 | AW36: - | AX36: 0 | AY36: 240 | AZ36: HUAWEI | BD36: 1 | BE36: 3 | BF36: COMPLETED | BG36: MBB | BH36: 14157.7 | BI36: 46081 | BJ36: 14 | BK36: 2838.3 | BL36: 46087 | BM36: 20 | BN36: 16996 | BO36: 528 | BP36: =G36&BG36 -> HAEMBB
A37: EP26020019 | B37: HAE-Cap_Q126-CWKWM | C37: CWKWM_2025 Capacity Expansion Ph8_EXP_ER | D37: 14111.38 | E37: 17209 | F37: 46066 | G37: HAE | H37: Cap_Q126 | I37: CWKWM | J37: BOONCHOT BORIWUT | K37: ER | L37: 46063 | M37: 46063 | N37: 46063 | O37: นาย อภิชาติ ฟังสันเทียะ | P37: VD00235 | Q37: SUBCON | R37: Adisak Chanmao | S37: น.ส. หทัยรัตน์ สิงห์แก้ว | T37: 26WK7 | U37: 793 | V37: 9674 | W37: 2579 | X37: 4163 | Y37: 17209 | Z37: 1056 | AA37: 46076 | AB37: 18265 | AC37: 10669.58 | AD37: 7840 | AE37: 7540 | AF37: 300 | AG37: 0 | AH37: Y | AI37: Y | AJ37: Y | AK37: 0 | AL37: 18926 | AM37: 15508.7 | AN37: 3417.3 | AO37: 18926 | AP37: 7900 | AQ37: 7780 | AR37: 18926 | AS37: 7780 | AT37: 0 | AU37: 46064 | AV37: 46068 | AW37: - | AX37: 0 | AY37: 60 | AZ37: HUAWEI | BD37: 1 | BE37: 5 | BF37: COMPLETED | BG37: MBB | BH37: 15508.7 | BI37: 46081 | BJ37: 18 | BK37: 3417.3 | BL37: 46087 | BM37: 24 | BN37: 18926 | BO37: 0 | BP37: =G37&BG37 -> HAEMBB
A38: EP26020029 | B38: TME-DIS_ATN-CBR0549 | C38: CBR0549-AC-02_D_Dismantle_EAST_R3 | D38: 1687.29 | E38: 2081 | F38: 46066 | G38: TME | H38: DIS_ATN | I38: CBR0549 | J38: BOONCHOT BORIWUT | K38: ER | L38: 46064 | M38: 46064 | N38: 46064 | O38: บริษัท สุพรรณ เทเลคอม จำกัด | P38: VD00327 | Q38: SUBCON | R38: Adisak Chanmao | S38: Sermsiri Bampentam | T38: 26WK7 | U38: 0 | V38: 1970 | W38: 0 | X38: 111 | Y38: 2081 | Z38: 0 | AA38: - | AB38: 2081 | AC38: 1500 | AD38: 1230 | AE38: 1230 | AF38: 0 | AG38: 0 | AH38: Y | AI38: Y | AJ38: Y | AK38: 0 | AL38: 2081 | AM38: 1687 | AN38: 394 | AO38: 2081 | AP38: 1230 | AQ38: 1230 | AR38: 2081 | AS38: 1230 | AT38: 0 | AU38: 46064 | AV38: 46076 | AW38: - | AX38: 0 | AY38: 0 | AZ38: HUAWEI | BD38: 0 | BE38: 12 | BF38: COMPLETED | BG38: IPRAN | BH38: 1687 | BI38: 46081 | BJ38: 17 | BK38: 394 | BL38: 46115 | BM38: 51 | BN38: 2081 | BO38: 0 | BP38: =G38&BG38 -> TMEIPRAN
A39: EP26020030 | B39: TME-DIS_ATN-CCO0015 | C39: CCO0015-AC-01_D_Dismantle_EAST_R3 | D39: 1687.29 | E39: 2081 | F39: 46066 | G39: TME | H39: DIS_ATN | I39: CCO0015 | J39: BOONCHOT BORIWUT | K39: ER | L39: 46063 | M39: 46063 | N39: 46063 | O39: นาย ชัชวาล เคราะห์ดี | P39: VD01205 | Q39: SUBCON | R39: Adisak Chanmao | S39: Sermsiri Bampentam | T39: 26WK7 | U39: 0 | V39: 1970 | W39: 0 | X39: 111 | Y39: 2081 | Z39: 0 | AA39: - | AB39: 2081 | AC39: 1500 | AD39: 1230 | AE39: 1230 | AF39: 0 | AG39: 0 | AH39: Y | AI39: Y | AJ39: Y | AK39: 0 | AL39: 2081 | AM39: 1687 | AN39: 0 | AO39: 1687 | AP39: 1230 | AQ39: 1230 | AR39: 1687 | AS39: 1230 | AT39: 0 | AU39: 46063 | AV39: 46076 | AW39: - | AX39: 394 | AY39: 0 | AZ39: HUAWEI | BD39: 0 | BE39: 13 | BF39: COMPLETED | BG39: IPRAN | BH39: 1687 | BI39: 46081 | BJ39: 18 | BK39: 394 | BL39: 46230 | BM39: 167 | BN39: 2081 | BO39: 0 | BP39: =G39&BG39 -> TMEIPRAN
A40: EP26020031 | B40: TME-DIS_ATN-CBI0073 | C40: CBI0073-AC-01_D_Dismantle_EAST_R3 | D40: 1687.29 | E40: 2081 | F40: 46066 | G40: TME | H40: DIS_ATN | I40: CBI0073 | J40: BOONCHOT BORIWUT | K40: ER | L40: 46065 | M40: 46065 | N40: 46065 | O40: นาย ชัชวาล เคราะห์ดี | P40: VD01205 | Q40: SUBCON | R40: Adisak Chanmao | S40: Sermsiri Bampentam | T40: 26WK7 | U40: 0 | V40: 1970 | W40: 0 | X40: 111 | Y40: 2081 | Z40: 0 | AA40: - | AB40: 2081 | AC40: 1500 | AD40: 1230 | AE40: 1230 | AF40: 0 | AG40: 0 | AH40: Y | AI40: Y | AJ40: Y | AK40: 0 | AL40: 2081 | AM40: 1687 | AN40: 394 | AO40: 2081 | AP40: 1230 | AQ40: 1230 | AR40: 2081 | AS40: 1230 | AT40: 0 | AU40: 46065 | AV40: 46076 | AW40: - | AX40: 0 | AY40: 0 | AZ40: HUAWEI | BD40: 0 | BE40: 11 | BF40: COMPLETED | BG40: IPRAN | BH40: 1687 | BI40: 46081 | BJ40: 16 | BK40: 394 | BL40: 46115 | BM40: 50 | BN40: 2081 | BO40: 0 | BP40: =G40&BG40 -> TMEIPRAN
...

Sheet Sheet1
B2: WEEK35 | C2: Column Labels | Q2: PMOwner | R2: BOONCHOT BORIWUT
C3: AC1 DONE | F3: FULFILLED | I3: UNFULFILL | L3: Total Count of P+L | M3: Total Sum of REVENUE | N3: Total Sum of REMAIN | Q3: STATUS WORK | R3: CONFIRMED
B4: Row Labels | C4: Count of P+L | D4: Sum of REVENUE | E4: Sum of REMAIN | F4: Count of P+L | G4: Sum of REVENUE | H4: Sum of REMAIN | I4: Count of P+L | J4: Sum of REVENUE | K4: Sum of REMAIN
B5: 2022 | F5: 3588 | G5: 8008048.9 | H5: 0 | L5: 3588 | M5: 8008048.9 | N5: 0 | Q5: Sum of REMAIN | R5: Column Labels
B6: 2023 | C6: 3 | D6: 38065 | E6: 11419.5 | F6: 5228 | G6: 11118732 | H6: 43613.1 | I6: 11 | J6: 78217 | K6: 78217 | L6: 5242 | M6: 11235014 | N6: 133249.6 | Q6: Row Labels | R6: HUAWEI | S6: Grand Total
B7: 2024 | F7: 5178 | G7: 14508273 | H7: 12891.9 | I7: 12 | J7: 60400 | K7: 60400 | L7: 5190 | M7: 14568673 | N7: 73291.9 | Q7: INSTALL ONPROCESS | R7: 820474 | S7: 820474
B8: 2025 | C8: 10 | D8: 31786 | E8: 9535.8 | F8: 3004 | G8: 8392750.2 | H8: 43148.1 | I8: 2 | J8: 24488 | K8: 24488 | L8: 3016 | M8: 8449024.2 | N8: 77171.9 | Q8: 2026 | R8: 820474 | S8: 820474
B9: 2026 | C9: 220 | D9: 676569 | E9: 203100.74 | F9: 1561 | G9: 3601009.4 | H9: 107470.92 | I9: 326 | J9: 935261 | K9: 935261 | L9: 2107 | M9: 5212839.4 | N9: 1245832.7 | Q9: Acceptance Plan AUGUST | R9: 324780.72 | S9: 324780.72
B10: Grand Total | C10: 233 | D10: 746420 | E10: 224056.04 | F10: 18559 | G10: 45628814 | H10: 207124.02 | I10: 351 | J10: 1098366 | K10: 1098366 | L10: 19143 | M10: 47473600 | N10: 1529546.1 | Q10: 2023 | R10: 87202.9 | S10: 87202.9
Q11: 2024 | R11: 62257 | S11: 62257
B12: WEEK36 | C12: Column Labels | Q12: 2025 | R12: 67636.1 | S12: 67636.1
C13: AC1 DONE | F13: FULFILLED | I13: UNFULFILL | L13: Total Count of P+L | M13: Total Sum of REVENUE | N13: Total Sum of REMAIN | Q13: 2026 | R13: 107684.72 | S13: 107684.72
B14: Row Labels | C14: Count of P+L | D14: Sum of REVENUE | E14: Sum of REMAIN | F14: Count of P+L | G14: Sum of REVENUE | H14: Sum of REMAIN | I14: Count of P+L | J14: Sum of REVENUE | K14: Sum of REMAIN | Q14: Acctance DONE AUGUST | R14: 29088 | S14: 29088
B15: 2022 | F15: 3588 | G15: 8008048.9 | H15: 0 | L15: 3588 | M15: 8008048.9 | N15: 0 | Q15: 2025 | R15: 29088 | S15: 29088
B16: 2023 | C16: 9 | D16: 118924 | E16: 25739.04 | F16: 5220 | G16: 11003308 | H16: 8985.9 | I16: 13 | J16: 112782 | K16: 112782 | L16: 5242 | M16: 11235014 | N16: 147506.94 | Q16: 2026 | R16: 0 | S16: 0
B17: 2024 | C17: 8 | D17: 36783 | E17: 7724.43 | F17: 5170 | G17: 14471490 | H17: 1857 | I17: 12 | J17: 60400 | K17: 60400 | L17: 5190 | M17: 14568673 | N17: 69981.43 | Q17: Acctance Plan AC#2 WK36 | R17: 110759.4 | S17: 110759.4
B18: 2025 | C18: 3 | D18: 69000 | E18: 27600 | F18: 2999 | G18: 8320147.2 | H18: 43148.1 | I18: 13 | J18: 57762 | K18: 57762 | L18: 3015 | M18: 8446909.2 | N18: 128510.1 | Q18: 2026 | R18: 110759.4 | S18: 110759.4
B19: 2026 | C19: 154 | D19: 472544 | E19: 142200.5 | F19: 1706 | G19: 4017920.4 | H19: 106536.12 | I19: 260 | J19: 768097 | K19: 768097 | L19: 2120 | M19: 5258561.4 | N19: 1016833.6 | Q19: Acctance Plan AC#1 WK36 | R19: 182483 | S19: 182483
B20: Grand Total | C20: 174 | D20: 697251 | E20: 203263.97 | F20: 18683 | G20: 45820915 | H20: 160527.12 | I20: 298 | J20: 999041 | K20: 999041 | L20: 19155 | M20: 47517207 | N20: 1362832.1 | Q20: 2026 | R20: 182483 | S20: 182483
Q21: Grand Total | R21: 1467585.1 | S21: 1467585.1
P27: AC1 | Q27: 2023
P28: AC1 | Q28: 2024
P29: AC1 | Q29: 2025
P30: AC1 | Q30: 2026 | R30: 182483
P32: AC2 | Q32: 2023
P33: AC2 | Q33: 2024
P34: AC2 | Q34: 2025 | R34: 29088
P35: AC2 | Q35: 2026 | R35: 110759.4
